Workbook

Sheet Tóm tắt
A1: BÁO CÁO KẾT QUẢ KIỂM THỬ: GIÁ MUA FCL (FCL BUYING)
A3: THÔNG TIN ĐỢT TEST
A4: Tính năng kiểm thử | B4: FCL Buying: Add new Buying, Edit, Delete, Send request, Accept, Reject, Revoke, Copy, Quickly create a Quotation, Switch To Edit
A6: KẾT QUẢ TEST CASE
A7: Tổng số test case | B7: =COUNTA('Test Case'!$A$4:$A$499) -> 133
A8: Pass | B8: =COUNTIF('Test Case'!$L$4:$L$499,"Pass") -> 117
A9: Fail | B9: =COUNTIF('Test Case'!$L$4:$L$499,"Fail") -> 16
A10: Blocked | B10: =COUNTIF('Test Case'!$L$4:$L$499,"Blocked") -> 0
A11: Not Run | B11: =COUNTIF('Test Case'!$L$4:$L$499,"Not Run") -> 0
A12: Đã thực hiện (Pass + Fail + Blocked) | B12: =B8+B9+B10 -> 133
A13: Tiến độ thực hiện | B13: =IF(B7=0,0,B12/B7) -> 1
A14: Tỷ lệ Pass (trên số đã thực hiện) | B14: =IF(B12=0,0,B8/B12) -> 0.87969925
A15: Test case Fail chưa có Bug ID | B15: =COUNTIFS('Test Case'!$L$4:$L$499,"Fail",'Test Case'!$N$4:$N$499,"") -> 0
A17: BUG | D17: CHECKLIST
A18: Tổng số bug | B18: =COUNTA('Bug Report'!$A$4:$A$14) -> 11 | D18: Tổng số mục kiểm tra | G18: =COUNTA(Checklist!$A$4:$A$503) -> 52
A19: Critical | B19: =COUNTIF('Bug Report'!$I$4:$I$14,"Critical") -> 2 | D19: Pass | G19: =COUNTIF(Checklist!$D$4:$D$503,"Pass") -> 45
A20: Major | B20: =COUNTIF('Bug Report'!$I$4:$I$14,"Major") -> 3 | D20: Fail | G20: =COUNTIF(Checklist!$D$4:$D$503,"Fail") -> 7
A21: Minor | B21: =COUNTIF('Bug Report'!$I$4:$I$14,"Minor") -> 6 | D21: Blocked | G21: =COUNTIF(Checklist!$D$4:$D$503,"Blocked") -> 0
A22: Trivial | B22: =COUNTIF('Bug Report'!$I$4:$I$14,"Trivial") -> 0 | D22: Not Run | G22: =COUNTIF(Checklist!$D$4:$D$503,"Not Run") -> 0
A23: Bug chưa đóng (không tính Closed, Rejected) | B23: =B18-COUNTIF('Bug Report'!$K$4:$K$14,"Closed")-COUNTIF('Bug Report'!$K$4:$K$14,"Rejected") -> 11
A25: KẾT QUẢ THEO SCENARIO
A26: Scenario | B26: Số TC | C26: Pass | D26: Fail | E26: Blocked | F26: Not Run | G26: % Pass
A27: =Scenario!A4&" - "&Scenario!B4 -> SC-01 - Hiển thị và giá trị mặc định của form tạo mới | B27: =Scenario!F4 -> 7 | C27: =Scenario!G4 -> 7 | D27: =Scenario!H4 -> 0 | E27: =Scenario!I4 -> 0 | F27: =Scenario!J4 -> 0 | G27: =ROUND(Scenario!L4, 2) -> 1
A28: =Scenario!A5&" - "&Scenario!B5 -> SC-02 - Tạo giá mua FCL thành công và các nút thao tác | B28: =Scenario!F5 -> 8 | C28: =Scenario!G5 -> 8 | D28: =Scenario!H5 -> 0 | E28: =Scenario!I5 -> 0 | F28: =Scenario!J5 -> 0 | G28: =ROUND(Scenario!L5, 2) -> 1
A29: =Scenario!A6&" - "&Scenario!B6 -> SC-03 - Kiểm tra trường bắt buộc | B29: =Scenario!F6 -> 10 | C29: =Scenario!G6 -> 10 | D29: =Scenario!H6 -> 0 | E29: =Scenario!I6 -> 0 | F29: =Scenario!J6 -> 0 | G29: =ROUND(Scenario!L6, 2) -> 1
A30: =Scenario!A7&" - "&Scenario!B7 -> SC-04 - Kiểm tra dữ liệu nhập | B30: =Scenario!F7 -> 14 | C30: =Scenario!G7 -> 4 | D30: =Scenario!H7 -> 10 | E30: =Scenario!I7 -> 0 | F30: =Scenario!J7 -> 0 | G30: =ROUND(Scenario!L7, 2) -> 0.29
A31: =Scenario!A8&" - "&Scenario!B8 -> SC-05 - Dropdown, lựa chọn và trường tùy chọn | B31: =Scenario!F8 -> 6 | C31: =Scenario!G8 -> 6 | D31: =Scenario!H8 -> 0 | E31: =Scenario!I8 -> 0 | F31: =Scenario!J8 -> 0 | G31: =ROUND(Scenario!L8, 2) -> 1
A32: =Scenario!A9&" - "&Scenario!B9 -> SC-06 - Ngày hiệu lực và hết hạn theo hợp đồng | B32: =Scenario!F9 -> 1 | C32: =Scenario!G9 -> 1 | D32: =Scenario!H9 -> 0 | E32: =Scenario!I9 -> 0 | F32: =Scenario!J9 -> 0 | G32: =ROUND(Scenario!L9, 2) -> 1
A33: =Scenario!A10&" - "&Scenario!B10 -> SC-07 - Bản ghi sau khi tạo tại tab Updating | B33: =Scenario!F10 -> 8 | C33: =Scenario!G10 -> 8 | D33: =Scenario!H10 -> 0 | E33: =Scenario!I10 -> 0 | F33: =Scenario!J10 -> 0 | G33: =ROUND(Scenario!L10, 2) -> 1
A34: =Scenario!A11&" - "&Scenario!B11 -> SC-08 - Gửi duyệt (Send request) đơn lẻ và hàng loạt | B34: =Scenario!F11 -> 12 | C34: =Scenario!G11 -> 12 | D34: =Scenario!H11 -> 0 | E34: =Scenario!I11 -> 0 | F34: =Scenario!J11 -> 0 | G34: =ROUND(Scenario!L11, 2) -> 1
A35: =Scenario!A12&" - "&Scenario!B12 -> SC-09 - Bản ghi sau khi gửi duyệt (tab Pending) | B35: =Scenario!F12 -> 6 | C35: =Scenario!G12 -> 6 | D35: =Scenario!H12 -> 0 | E35: =Scenario!I12 -> 0 | F35: =Scenario!J12 -> 0 | G35: =ROUND(Scenario!L12, 2) -> 1
A36: =Scenario!A13&" - "&Scenario!B13 -> SC-10 - Duyệt (Accept) và từ chối (Reject) đơn lẻ và hàng loạt | B36: =Scenario!F13 -> 15 | C36: =Scenario!G13 -> 14 | D36: =Scenario!H13 -> 1 | E36: =Scenario!I13 -> 0 | F36: =Scenario!J13 -> 0 | G36: =ROUND(Scenario!L13, 2) -> 0.93
A37: =Scenario!A14&" - "&Scenario!B14 -> SC-11 - Bản ghi sau khi duyệt (tab Accepted) | B37: =Scenario!F14 -> 18 | C37: =Scenario!G14 -> 17 | D37: =Scenario!H14 -> 1 | E37: =Scenario!I14 -> 0 | F37: =Scenario!J14 -> 0 | G37: =ROUND(Scenario!L14, 2) -> 0.94
A38: =Scenario!A15&" - "&Scenario!B15 -> SC-12 - Bản ghi sau khi từ chối (tab Rejected) | B38: =Scenario!F15 -> 7 | C38: =Scenario!G15 -> 7 | D38: =Scenario!H15 -> 0 | E38: =Scenario!I15 -> 0 | F38: =Scenario!J15 -> 0 | G38: =ROUND(Scenario!L15, 2) -> 1
... A43: =Scenario!A20&" - "&Scenario!B20 -> SC-17 - Luồng end-to-end | B43: =Scenario!F20 -> 5 | C43: =Scenario!G20 -> 5 | D43: =Scenario!H20 -> 0 | E43: =Scenario!I20 -> 0 | F43: =Scenario!J20 -> 0 | G43: =ROUND(Scenario!L20, 2) -> 1

Sheet Nghiệp vụ
A1: TÓM TẮT NGHIỆP VỤ: GIÁ MUA FCL (FCL BUYING)
A3: 1. TỔNG QUAN
A4: Mục | B4: Nội dung
A5: Tính năng | B5: Quản lý giá mua cước vận chuyển container nguyên (FCL Buying) trong module Pricing > FCL Pricing > FCL Buying của hệ thống quản lý logistics
A6: Mục đích | B6: Hỗ trợ người dùng tạo bảng giá thuê ngoài cho container nguyên
A7: Phạm vi tài liệu này | B7: Kiểm thử giao diện (UI): Add new Buying; Edit, Delete, Send request, Accept, Reject, Revoke, Copy, Quickly create a Quotation, Switch To Edit
A8: Ngoài phạm vi | B8: menu Dollar
A10: 2. LUỒNG TRẠNG THÁI (CÁC TAB)
A11: Tab / trạng thái | B11: Cách vào | C11: Thao tác cho phép (menu 3 chấm) | D11: Ghi chú
A12: Updating (Chờ cập nhật) | B12: Sau khi tạo mới thành công | C12: Send request, Edit, Delete
A13: Pending (Chờ duyệt) | B13: Sau khi Send request | C13: Accept, Reject, Edit
A14: Accepted (Đã duyệt) | B14: Sau khi Accept | C14: Revoke, Copy, Quickly create a Quotation
A15: Rejected (Từ chối) | B15: Sau khi Reject | C15: Switch To Edit
A16: Revoked (Hủy) | B16: Sau khi Revoke | C16: Chỉ xem
A18: 3. CÁC TRƯỜNG TRÊN FORM TẠO MỚI
A19: Trường | B19: Bắt buộc | C19: Giá trị mặc định | D19: Ghi chú
A20: Supplier / Weight Range / Container Type | B20: Có | C20: Trống | D20: Dropdown
A21: Place From / Place To | B21: Có | C21: Trống | D21: Dropdown
A22: Place of Receipt (Empty) | B22: Không | C22: Trống | D22: Chỉ chọn 1 giá trị; nút + bị vô hiệu hóa
A23: Place of Loading/Unloading / Place of Return (Empty) | B23: Không | C23: Trống | D23: Chọn nhiều giá trị; nút + mở popup chọn từ danh sách
A24: Service Type | B24: Có | C24: Transportation | D24: Dropdown
A25: Customer | B25: Không | C25: Trống | D25: Dropdown; ảnh hưởng danh sách Contract No
A26: Mode Of Transport / Weekdays | B26: Có | C26: Trống | D26: Dropdown; chọn nhiều giá trị
A27: Contract No | B27: Không | C27: Trống | D27: Dropdown; Effective On và Expiry On của bản ghi lấy theo hợp đồng này; bắt buộc khi Send request
A28: Currency | B28: Có | C28: Giá trị tick Default ở menu Catalogue > Currency | D28: Dropdown
A29: Price | B29: Có | C29: Trống | D29: Số, có mũi tên tăng/giảm. CONFIRM: giá = 0 có hợp lệ không
A30: VAT Rate | B30: Không | C30: Mã VATRate theo Effective On (ngày hiện tại) ở menu Accounting > Parameters | D30: Số, có mũi tên tăng/giảm
... A34: Status | B34: Không | C34: Tick | D34: Công tắc
A35: Nút thao tác | D35: Cancel, Save and Continue, Save
A37: 4. QUY TẮC NGHIỆP VỤ
A38: Mã | B38: Quy tắc | C38: Nguồn | D38: Trạng thái
A39: ="BR-"&TEXT(ROW()-39,"00") -> BR-00 | B39: Bản ghi mới tạo thành công nằm ở tab Updating | C39: Tài liệu
A40: ="BR-"&TEXT(ROW()-39,"00") -> BR-01 | B40: Delete có xác nhận trước khi xóa | C40: Tài liệu
A41: ="BR-"&TEXT(ROW()-39,"00") -> BR-02 | B41: Send request bắt buộc có Contract No; ghi chú không bắt buộc; bản ghi chuyển sang tab Pending | C41: Tài liệu
A42: ="BR-"&TEXT(ROW()-39,"00") -> BR-03 | B42: Bản ghi ở tab Pending có thể Accept (ghi chú không bắt buộc), bản ghi chuyển sang tab Accepted hoặc Reject (ghi chú bắt buộc), bản ghi chuyển sang tab Rejected | C42: Tài liệu
A43: ="BR-"&TEXT(ROW()-39,"00") -> BR-04 | B43: Edit ở tab Pending chỉ sửa được 6 trường: Place of Receipt, Place of Loading/Unloading, Place of Return (Empty), Contract No, Status, Note | C43: Tài liệu
A44: ="BR-"&TEXT(ROW()-39,"00") -> BR-05 | B44: Bản ghi ở tab Accepted có thể Revoke (ghi chú bắt buộc); bản ghi chuyển sang tab Revoked | C44: Tài liệu
A45: ="BR-"&TEXT(ROW()-39,"00") -> BR-06 | B45: Copy mở popup thêm mới, sao chép tất cả trường trừ Project Name, Return Assoc Freight Percent, Canceled Freight Percent, Note, Status, Dangerous Goods, Refrigerated Goods | C45: Tài liệu
A46: ="BR-"&TEXT(ROW()-39,"00") -> BR-07 | B46: Quickly create a Quotation chuyển sang menu Quotation > Create FCL Quotation, điền sẵn dữ liệu Create FCL Quotation tương ứng với FCL Buying: Customer, Container Type, Project Name, Weight Range, Place Of Loading = Place From, Place Of Discharge = Place To, Weekdays, Place Of Receipt(empty), Place of Loading/Unloading, Place of Return(empty), Supplier, Min cost = Price, Currency | C46: Tài liệu
A47: ="BR-"&TEXT(ROW()-39,"00") -> BR-08 | B47: Bản ghi ở tab Rejected có thể Switch To Edit chuyển bản ghi về tab Updating, dữ liệu giá mua FCL không thay đổi
...

Sheet Scenario
A1: TEST SCENARIO VÀ TRUY VẾT
A2: Mỗi test case gắn 1 scenario chính (cột Scenario ở sheet Test Case)
A3: Scenario ID | B3: Tên scenario | C3: Mục tiêu kiểm thử | D3: Độ ưu tiên | E3: Test case liên quan | F3: Số TC | G3: Pass | H3: Fail | I3: Blocked | J3: Not Run | K3: % Đã chạy | L3: % Pass (trên đã chạy)
A4: SC-01 | B4: Hiển thị và giá trị mặc định của form tạo mới | C4: Form đủ trường, dấu (*), giá trị mặc định (Service Type, Currency, VAT Rate), trạng thái nút + | D4: Medium | E4: TC-FB-001 đến 007 | F4: =COUNTIF('Test Case'!$B$4:$B$499,A4) -> 7 | G4: =COUNTIFS('Test Case'!$B$4:$B$499,A4,'Test Case'!$L$4:$L$499,"Pass") -> 7 | H4: =COUNTIFS('Test Case'!$B$4:$B$499,A4,'Test Case'!$L$4:$L$499,"Fail") -> 0 | I4: =COUNTIFS('Test Case'!$B$4:$B$499,A4,'Test Case'!$L$4:$L$499,"Blocked") -> 0 | J4: =COUNTIFS('Test Case'!$B$4:$B$499,A4,'Test Case'!$L$4:$L$499,"Not Run") -> 0 | K4: =IF(F4=0,0,(G4+H4+I4)/F4) -> 1 | L4: =ROUND(IF((G4+H4+I4)=0,0,G4/(G4+H4+I4)),2) -> 1
A5: SC-02 | B5: Tạo giá mua FCL thành công và các nút thao tác | C5: Kiểm tra tạo bản ghi thành công (Save, Save and Continue, chống trùng, sinh mã Code, chống double-click), nút Cancel và đóng form không lưu dữ liệu | D5: High | E5: TC-FB-008 đến 015 | F5: =COUNTIF('Test Case'!$B$4:$B$499,A5) -> 8 | G5: =COUNTIFS('Test Case'!$B$4:$B$499,A5,'Test Case'!$L$4:$L$499,"Pass") -> 8 | H5: =COUNTIFS('Test Case'!$B$4:$B$499,A5,'Test Case'!$L$4:$L$499,"Fail") -> 0 | I5: =COUNTIFS('Test Case'!$B$4:$B$499,A5,'Test Case'!$L$4:$L$499,"Blocked") -> 0 | J5: =COUNTIFS('Test Case'!$B$4:$B$499,A5,'Test Case'!$L$4:$L$499,"Not Run") -> 0 | K5: =IF(F5=0,0,(G5+H5+I5)/F5) -> 1 | L5: =ROUND(IF((G5+H5+I5)=0,0,G5/(G5+H5+I5)),2) -> 1
A6: SC-03 | B6: Kiểm tra trường bắt buộc | C6: Không lưu được khi thiếu trường có dấu (*); xử lý VAT Rate bị xóa giá trị mặc định | D6: High | E6: TC-FB-016 đến 025 | F6: =COUNTIF('Test Case'!$B$4:$B$499,A6) -> 10 | G6: =COUNTIFS('Test Case'!$B$4:$B$499,A6,'Test Case'!$L$4:$L$499,"Pass") -> 10 | H6: =COUNTIFS('Test Case'!$B$4:$B$499,A6,'Test Case'!$L$4:$L$499,"Fail") -> 0 | I6: =COUNTIFS('Test Case'!$B$4:$B$499,A6,'Test Case'!$L$4:$L$499,"Blocked") -> 0 | J6: =COUNTIFS('Test Case'!$B$4:$B$499,A6,'Test Case'!$L$4:$L$499,"Not Run") -> 0 | K6: =IF(F6=0,0,(G6+H6+I6)/F6) -> 1 | L6: =ROUND(IF((G6+H6+I6)=0,0,G6/(G6+H6+I6)),2) -> 1
A7: SC-04 | B7: Kiểm tra dữ liệu nhập | C7: Price, VAT Rate, % cước, Note, Project Name: giá trị hợp lệ, sai định dạng, giá trị biên | D7: High | E7: TC-FB-026 đến 039 | F7: =COUNTIF('Test Case'!$B$4:$B$499,A7) -> 14 | G7: =COUNTIFS('Test Case'!$B$4:$B$499,A7,'Test Case'!$L$4:$L$499,"Pass") -> 4 | H7: =COUNTIFS('Test Case'!$B$4:$B$499,A7,'Test Case'!$L$4:$L$499,"Fail") -> 10 | I7: =COUNTIFS('Test Case'!$B$4:$B$499,A7,'Test Case'!$L$4:$L$499,"Blocked") -> 0 | J7: =COUNTIFS('Test Case'!$B$4:$B$499,A7,'Test Case'!$L$4:$L$499,"Not Run") -> 0 | K7: =IF(F7=0,0,(G7+H7+I7)/F7) -> 1 | L7: =ROUND(IF((G7+H7+I7)=0,0,G7/(G7+H7+I7)),2) -> 0.29
A8: SC-05 | B8: Dropdown, lựa chọn và trường tùy chọn | C8: Place (chọn 1 hoặc nhiều giá trị), Customer, Contract No, Weekday | D8: Medium | E8: TC-FB-040 đến 045 | F8: =COUNTIF('Test Case'!$B$4:$B$499,A8) -> 6 | G8: =COUNTIFS('Test Case'!$B$4:$B$499,A8,'Test Case'!$L$4:$L$499,"Pass") -> 6 | H8: =COUNTIFS('Test Case'!$B$4:$B$499,A8,'Test Case'!$L$4:$L$499,"Fail") -> 0 | I8: =COUNTIFS('Test Case'!$B$4:$B$499,A8,'Test Case'!$L$4:$L$499,"Blocked") -> 0 | J8: =COUNTIFS('Test Case'!$B$4:$B$499,A8,'Test Case'!$L$4:$L$499,"Not Run") -> 0 | K8: =IF(F8=0,0,(G8+H8+I8)/F8) -> 1 | L8: =ROUND(IF((G8+H8+I8)=0,0,G8/(G8+H8+I8)),2) -> 1
A9: SC-06 | B9: Ngày hiệu lực và hết hạn theo hợp đồng | C9: Effective On, Expiry On lấy đúng theo hợp đồng (Contract No) khi tạo | D9: High | E9: TC-FB-046 | F9: =COUNTIF('Test Case'!$B$4:$B$499,A9) -> 1 | G9: =COUNTIFS('Test Case'!$B$4:$B$499,A9,'Test Case'!$L$4:$L$499,"Pass") -> 1 | H9: =COUNTIFS('Test Case'!$B$4:$B$499,A9,'Test Case'!$L$4:$L$499,"Fail") -> 0 | I9: =COUNTIFS('Test Case'!$B$4:$B$499,A9,'Test Case'!$L$4:$L$499,"Blocked") -> 0 | J9: =COUNTIFS('Test Case'!$B$4:$B$499,A9,'Test Case'!$L$4:$L$499,"Not Run") -> 0 | K9: =IF(F9=0,0,(G9+H9+I9)/F9) -> 1 | L9: =ROUND(IF((G9+H9+I9)=0,0,G9/(G9+H9+I9)),2) -> 1
A10: SC-07 | B10: Bản ghi sau khi tạo tại tab Updating | C10: Bản ghi hiển thị và đúng hành đông; số đếm; thao tác Edit và Delete | D10: High | E10: TC-FB-047 đến 054 | F10: =COUNTIF('Test Case'!$B$4:$B$499,A10) -> 8 | G10: =COUNTIFS('Test Case'!$B$4:$B$499,A10,'Test Case'!$L$4:$L$499,"Pass") -> 8 | H10: =COUNTIFS('Test Case'!$B$4:$B$499,A10,'Test Case'!$L$4:$L$499,"Fail") -> 0 | I10: =COUNTIFS('Test Case'!$B$4:$B$499,A10,'Test Case'!$L$4:$L$499,"Blocked") -> 0 | J10: =COUNTIFS('Test Case'!$B$4:$B$499,A10,'Test Case'!$L$4:$L$499,"Not Run") -> 0 | K10: =IF(F10=0,0,(G10+H10+I10)/F10) -> 1 | L10: =ROUND(IF((G10+H10+I10)=0,0,G10/(G10+H10+I10)),2) -> 1
A11: SC-08 | B11: Gửi duyệt (Send request) đơn lẻ và hàng loạt | C11: Send request đơn lẻ và hàng loạt bắt buộc có Contract No, ghi chú không bắt buộc | D11: High | E11: TC-FB-055 đến 066 | F11: =COUNTIF('Test Case'!$B$4:$B$499,A11) -> 12 | G11: =COUNTIFS('Test Case'!$B$4:$B$499,A11,'Test Case'!$L$4:$L$499,"Pass") -> 12 | H11: =COUNTIFS('Test Case'!$B$4:$B$499,A11,'Test Case'!$L$4:$L$499,"Fail") -> 0 | I11: =COUNTIFS('Test Case'!$B$4:$B$499,A11,'Test Case'!$L$4:$L$499,"Blocked") -> 0 | J11: =COUNTIFS('Test Case'!$B$4:$B$499,A11,'Test Case'!$L$4:$L$499,"Not Run") -> 0 | K11: =IF(F11=0,0,(G11+H11+I11)/F11) -> 1 | L11: =ROUND(IF((G11+H11+I11)=0,0,G11/(G11+H11+I11)),2) -> 1
A12: SC-09 | B12: Bản ghi sau khi gửi duyệt (tab Pending) | C12: Bản ghi hiển thị và đúng hành đông; số đếm; thao tác Edit (chỉ được 6 trường: Place of Receipt, Loading/Unloading, Return, Contract No, Status, Note) | D12: High | E12: TC-FB-067 đến 072 | F12: =COUNTIF('Test Case'!$B$4:$B$499,A12) -> 6 | G12: =COUNTIFS('Test Case'!$B$4:$B$499,A12,'Test Case'!$L$4:$L$499,"Pass") -> 6 | H12: =COUNTIFS('Test Case'!$B$4:$B$499,A12,'Test Case'!$L$4:$L$499,"Fail") -> 0 | I12: =COUNTIFS('Test Case'!$B$4:$B$499,A12,'Test Case'!$L$4:$L$499,"Blocked") -> 0 | J12: =COUNTIFS('Test Case'!$B$4:$B$499,A12,'Test Case'!$L$4:$L$499,"Not Run") -> 0 | K12: =IF(F12=0,0,(G12+H12+I12)/F12) -> 1 | L12: =ROUND(IF((G12+H12+I12)=0,0,G12/(G12+H12+I12)),2) -> 1
A13: SC-10 | B13: Duyệt (Accept) và từ chối (Reject) đơn lẻ và hàng loạt | C13: Accept (ghi chú không bắt buộc) và Reject (ghi chú bắt buộc) đơn lẻ và hàng loạt, xử lý đồng thời | D13: High | E13: TC-FB-073 đến 087 | F13: =COUNTIF('Test Case'!$B$4:$B$499,A13) -> 15 | G13: =COUNTIFS('Test Case'!$B$4:$B$499,A13,'Test Case'!$L$4:$L$499,"Pass") -> 14 | H13: =COUNTIFS('Test Case'!$B$4:$B$499,A13,'Test Case'!$L$4:$L$499,"Fail") -> 1 | I13: =COUNTIFS('Test Case'!$B$4:$B$499,A13,'Test Case'!$L$4:$L$499,"Blocked") -> 0 | J13: =COUNTIFS('Test Case'!$B$4:$B$499,A13,'Test Case'!$L$4:$L$499,"Not Run") -> 0 | K13: =IF(F13=0,0,(G13+H13+I13)/F13) -> 1 | L13: =ROUND(IF((G13+H13+I13)=0,0,G13/(G13+H13+I13)),2) -> 0.93
A14: SC-11 | B14: Bản ghi sau khi duyệt (tab Accepted) | C14: Kiểm tra bản ghi hiển thị và đúng hành đông; thao tác Revoke (ghi chú bắt buộc) đơn lẻ và hàng loạt, Copy và Quickly create a Quotation | D14: Medium | E14: TC-FB-088 đến 105 | F14: =COUNTIF('Test Case'!$B$4:$B$499,A14) -> 18 | G14: =COUNTIFS('Test Case'!$B$4:$B$499,A14,'Test Case'!$L$4:$L$499,"Pass") -> 17 | H14: =COUNTIFS('Test Case'!$B$4:$B$499,A14,'Test Case'!$L$4:$L$499,"Fail") -> 1 | I14: =COUNTIFS('Test Case'!$B$4:$B$499,A14,'Test Case'!$L$4:$L$499,"Blocked") -> 0 | J14: =COUNTIFS('Test Case'!$B$4:$B$499,A14,'Test Case'!$L$4:$L$499,"Not Run") -> 0 | K14: =IF(F14=0,0,(G14+H14+I14)/F14) -> 1 | L14: =ROUND(IF((G14+H14+I14)=0,0,G14/(G14+H14+I14)),2) -> 0.94
A15: SC-12 | B15: Bản ghi sau khi từ chối (tab Rejected) | C15: Bản ghi hiển thị và đúng hành đông; thao tác Switch To Edit (Chuyển bản ghi Rejected về Updating, sửa và gửi duyệt lại) đơn lẻ và hàng loạt | D15: High | E15: TC-FB-106 đến 112 | F15: =COUNTIF('Test Case'!$B$4:$B$499,A15) -> 7 | G15: =COUNTIFS('Test Case'!$B$4:$B$499,A15,'Test Case'!$L$4:$L$499,"Pass") -> 7 | H15: =COUNTIFS('Test Case'!$B$4:$B$499,A15,'Test Case'!$L$4:$L$499,"Fail") -> 0 | I15: =COUNTIFS('Test Case'!$B$4:$B$499,A15,'Test Case'!$L$4:$L$499,"Blocked") -> 0 | J15: =COUNTIFS('Test Case'!$B$4:$B$499,A15,'Test Case'!$L$4:$L$499,"Not Run") -> 0 | K15: =IF(F15=0,0,(G15+H15+I15)/F15) -> 1 | L15: =ROUND(IF((G15+H15+I15)=0,0,G15/(G15+H15+I15)),2) -> 1
... A20: SC-17 | B20: Luồng end-to-end | C20: Luồng trọn vẹn, số đếm các tab, refresh trang, bộ lọc | D20: High | E20: TC-FB-129 đến 133 | F20: =COUNTIF('Test Case'!$B$4:$B$499,A20) -> 5 | G20: =COUNTIFS('Test Case'!$B$4:$B$499,A20,'Test Case'!$L$4:$L$499,"Pass") -> 5 | H20: =COUNTIFS('Test Case'!$B$4:$B$499,A20,'Test Case'!$L$4:$L$499,"Fail") -> 0 | I20: =COUNTIFS('Test Case'!$B$4:$B$499,A20,'Test Case'!$L$4:$L$499,"Blocked") -> 0 | J20: =COUNTIFS('Test Case'!$B$4:$B$499,A20,'Test Case'!$L$4:$L$499,"Not Run") -> 0 | K20: =IF(F20=0,0,(G20+H20+I20)/F20) -> 1 | L20: =ROUND(IF((G20+H20+I20)=0,0,G20/(G20+H20+I20)),2) -> 1
A21: Tổng | F21: =SUM(F4:F20) -> 133 | G21: =SUM(G4:G20) -> 117 | H21: =SUM(H4:H20) -> 16 | I21: =SUM(I4:I20) -> 0 | J21: =SUM(J4:J20) -> 0 | K21: =IF(F21=0,0,(G21+H21+I21)/F21) -> 1 | L21: =ROUND(IF((G21+H21+I21)=0,0,G21/(G21+H21+I21)),2) -> 0.88

Sheet Checklist
A1: CHECKLIST KIỂM TRA NHANH
A2: Mỗi dòng là một điểm kiểm tra chính. Dùng để smoke test nhanh và để người xem nắm tổng quan. Chi tiết xem ở sheet Test Case.
A3: Mã | B3: Scenario | C3: Mục kiểm tra | D3: Kết quả | E3: Bug ID | F3: Ghi chú | G3: Test case chi tiết
A4: ="CL-"&TEXT(ROW()-3,"000") -> CL-001 | B4: SC-01 | C4: Form tạo mới hiển thị đầy đủ trường, dấu (*) và trạng thái nút + mặc định | D4: Pass | G4: TC-FB-001
A5: ="CL-"&TEXT(ROW()-3,"000") -> CL-002 | B5: SC-01 | C5: Biểu tượng thông tin (i) | D5: Pass | G5: TC-FB-002
A6: ="CL-"&TEXT(ROW()-3,"000") -> CL-003 | B6: SC-01 | C6: Giá trị mặc định đúng: Service Type, Currency, VAT Rate, Status | D6: Pass | G6: TC-FB-003 đến 007
A7: ="CL-"&TEXT(ROW()-3,"000") -> CL-004 | B7: SC-02 | C7: Tạo thành công chỉ với các trường bắt buộc | D7: Pass | G7: TC-FB-008
A8: ="CL-"&TEXT(ROW()-3,"000") -> CL-005 | B8: SC-02 | C8: Tạo thành công với đầy đủ tất cả các trường | D8: Pass | G8: TC-FB-009
A9: ="CL-"&TEXT(ROW()-3,"000") -> CL-006 | B9: SC-02 | C9: Save and Continue, Cancel và nút đóng hoạt động đúng | D9: Pass | G9: TC-FB-010 đến 012
A10: ="CL-"&TEXT(ROW()-3,"000") -> CL-007 | B10: SC-02 | C10: Chống trùng, sinh mã Code tự động, chống double-click nút Save | D10: Pass | G10: TC-FB-013 đến 015
A11: ="CL-"&TEXT(ROW()-3,"000") -> CL-008 | B11: SC-03 | C11: Bỏ trống toàn bộ form bị chặn | D11: Pass | G11: TC-FB-016
A12: ="CL-"&TEXT(ROW()-3,"000") -> CL-009 | B12: SC-03 | C12: Bỏ trống từng trường bắt buộc đều bị chặn | D12: Pass | G12: TC-FB-017 đến 024
A13: ="CL-"&TEXT(ROW()-3,"000") -> CL-010 | B13: SC-03 | C13: Xóa giá trị mặc định của VAT Rate xử lý đúng | D13: Pass | G13: TC-FB-025
A14: ="CL-"&TEXT(ROW()-3,"000") -> CL-011 | B14: SC-04 | C14: Price, VAT Rate: ký tự chữ, số âm, bằng 0, >100 xử lý đúng. Nút tăng giảm xử lý đúng | D14: Fail | E14: BUG-001; BUG-002; BUG-003 | F14: TC-FB-027, TC-FB-028; TC-FB-029, TC-FB-030; TC-FB-031 | G14: TC-FB-026 đến 031
A15: ="CL-"&TEXT(ROW()-3,"000") -> CL-012 | B15: SC-04 | C15: Freight Percent sai định dạng bị chặn, đúng định dạng lưu được | D15: Fail | E15: BUG-004 | F15: TC-FB-033, TC-FB-034, TC-FB-035 | G15: TC-FB-032 đến 035
A16: ="CL-"&TEXT(ROW()-3,"000") -> CL-013 | B16: SC-04 | C16: Note, Project Name: tiếng Việt, ký tự đặc biệt, khoảng trắng, độ dài | D16: Fail | E16: BUG-005; BUG-006 | F16: TC-FB-037; TC-FB-039 | G16: TC-FB-036 đến 039
A17: ="CL-"&TEXT(ROW()-3,"000") -> CL-014 | B17: SC-05 | C17: Dropdown tìm kiếm được | D17: Pass | G17: TC-FB-040
A18: ="CL-"&TEXT(ROW()-3,"000") -> CL-015 | B18: SC-05 | C18: Danh sách Contract No theo Customer đã chọn | D18: Pass | G18: TC-FB-041
A19: ="CL-"&TEXT(ROW()-3,"000") -> CL-016 | B19: SC-05 | C19: Weekdays chọn nhiều ngày | D19: Pass | G19: TC-FB-042
A20: ="CL-"&TEXT(ROW()-3,"000") -> CL-017 | B20: SC-05 | C20: Popup chọn nhiều giá trị ở Place of Loading/Unloading và Place of Return | D20: Pass | G20: TC-FB-043 đến 044
A21: ="CL-"&TEXT(ROW()-3,"000") -> CL-018 | B21: SC-05 | C21: Place of Receipt chỉ chọn 1 giá trị | D21: Pass | G21: TC-FB-045
A22: ="CL-"&TEXT(ROW()-3,"000") -> CL-019 | B22: SC-06 | C22: Effective On, Expiry On khớp ngày của hợp đồng đã chọn | D22: Pass | G22: TC-FB-046
A23: ="CL-"&TEXT(ROW()-3,"000") -> CL-020 | B23: SC-07 | C23: Bản ghi mới vào tab Updating, dữ liệu và số đếm đúng; menu 3 chấm đúng thao tác | D23: Pass | G23: TC-FB-047 đến 048
A24: ="CL-"&TEXT(ROW()-3,"000") -> CL-021 | B24: SC-07 | C24: Edit ở tab Updating: lưu đúng, chặn trường bắt buộc, hủy không lưu | D24: Pass | G24: TC-FB-049 đến 052
A25: ="CL-"&TEXT(ROW()-3,"000") -> CL-022 | B25: SC-07 | C25: Delete có xác nhận: hủy thì không xóa, xác nhận thì xóa | D25: Pass | G25: TC-FB-053 đến 054
A26: ="CL-"&TEXT(ROW()-3,"000") -> CL-023 | B26: SC-08 | C26: Send request có Contract No xử lý đúng | D26: Pass | G26: TC-FB-055 đến TC-FB-056
A27: ="CL-"&TEXT(ROW()-3,"000") -> CL-024 | B27: SC-08 | C27: Ghi chú tiếng Việt, quá dài; đóng popup; Send request click nhiều lần xử lý đúng | D27: Pass | G27: TC-FB-057 đến 060
A28: ="CL-"&TEXT(ROW()-3,"000") -> CL-025 | B28: SC-08 | C28: Bản ghi chưa có Contract No không Send request được | D28: Pass | G28: TC-FB-061
... A36: ="CL-"&TEXT(ROW()-3,"000") -> CL-033 | B36: SC-10 | C36: Reject hàng loạt, xử lý bản ghi thiếu ghi chú khi Reject | D36: Pass | G36: TC-FB-0833 đến 086
A37: ="CL-"&TEXT(ROW()-3,"000") -> CL-034 | B37: SC-10 | C37: Dữ liệu giữ nguyên sau Accept; hai người xử lý cùng bản ghi | D37: Fail | E37: BUG-007 | F37: TC-FB-087 | G37: TC-FB-087
A38: ="CL-"&TEXT(ROW()-3,"000") -> CL-035 | B38: SC-11 | C38: Bản ghi mới vào tab Accepted hiển thị đúng thao tác | D38: Pass | G38: TC-FB-088
A39: ="CL-"&TEXT(ROW()-3,"000") -> CL-036 | B39: SC-11 | C39: Revoke bắt buộc ghi chú: bản ghi chuyển sang tab Revoked | D39: Pass | G39: TC-FB-089 đến 091
A40: ="CL-"&TEXT(ROW()-3,"000") -> CL-037 | B40: SC-11 | C40: Revoke hàng loạt, xử lý bản ghi thiếu ghi chú | D40: Pass | G40: TC-FB-092 đến 095
A41: ="CL-"&TEXT(ROW()-3,"000") -> CL-038 | B41: SC-11 | C41: Copy mở popup thêm mới, sao chép đúng các trường; trường loại trừ để trống hoặc mặc định | D41: Pass | G41: TC-FB-096 đến 097
A42: ="CL-"&TEXT(ROW()-3,"000") -> CL-039 | B42: SC-11 | C42: Lưu bản sao: Code mới, nằm ở tab Updating; đóng popup và kiểm tra dữ liệu đúng | D42: Pass | G42: TC-FB-097 đến 099
A43: ="CL-"&TEXT(ROW()-3,"000") -> CL-040 | B43: SC-11 | C43: Quickly create a Quotation chuyển đúng màn hình, điền sẵn đúng dữ liệu (kể cả trường nhiều giá trị) | D43: Fail | E43: BUG-008 | F43: TC-FB-101 | G43: TC-FB-100 đến 102
A44: ="CL-"&TEXT(ROW()-3,"000") -> CL-041 | B44: SC-11 | C44: Quickly create a Quotation: trường trống, lưu báo giá, bản ghi giá mua không đổi | D44: Pass | G44: TC-FB-103 đến 105
A45: ="CL-"&TEXT(ROW()-3,"000") -> CL-042 | B45: SC-12 | C45: Switch To Edit đưa bản ghi Rejected về Updating và Send request | D45: Pass | G45: TC-FB-106 đến 108
A46: ="CL-"&TEXT(ROW()-3,"000") -> CL-043 | B46: SC-12 | C46: Switch To Edit hàng loạt | D46: Pass | G46: TC-FB-109 đến 111
A47: ="CL-"&TEXT(ROW()-3,"000") -> CL-044 | B47: SC-12 | C47: Bản ghi mới vào tab Rejected hiển thị đúng thao tác | D47: Pass | G47: TC-FB-112
...

Sheet Test Case
A1: TEST CASE: GIÁ MUA FCL (UI)
A3: TC ID | B3: Scenario | C3: Module | D3: Chức năng | E3: Loại test | F3: Mô tả test case | G3: Precondition | H3: Test data | I3: Các bước thực hiện | J3: Kết quả mong đợi | K3: Kết quả thực tế | L3: Trạng thái | M3: Độ ưu tiên | N3: Bug ID | O3: Người test | P3: Ngày test | Q3: Ghi chú
A4: ="TC-FB-"&TEXT(ROW()-3,"000") -> TC-FB-001 | B4: SC-01 | C4: FCL Buying | D4: Add new Buying | E4: UI | F4: Form tạo mới hiển thị đầy đủ trường, dấu (*) và trạng thái nút + mặc định | G4: Đăng nhập role có quyền Add | H4: Không cần dữ liệu | I4: 1. Vào Pricing > FCL Pricing > FCL Buying 2. Nhấn nút Add New Buying để mở form tạo mới 3. Quan sát toàn bộ form 4. Đối chiếu nhãn, dấu (*) và trạng thái các nút + từng trường 5. So sánh với tài liệu nghiệp vụ | J4: Form có đủ: Supplier, Place From, Place To, Place of Receipt, Place of Loading/Unloading, Place of Return, Service Type, Customer, Mode Of Transport, Weight Range, Container Type, Contract No, Weekdays, Currency, Price, VAT Rate, Include VAT, Project Name, Return Assoc Freight Percent, Canceled Freight Percent, Note, Status, Dangerous Goods, Refrigerated Goods, nút Cancel, Save and Continue, Save. Dấu (*) đỏ ở: Supplier, Place From, Place To, Service Type, Mode Of Transport, Weight Range, Container Type, Currency, Price. Nút + cạnh Place of Loading/Unloading và Place of Return đang bật (màu xanh đậm, click được); nút + cạnh Place of Receipt (Empty) bị vô hiệu hóa (màu nhạt, không click được) | L4: Pass | M4: Medium
A5: ="TC-FB-"&TEXT(ROW()-3,"000") -> TC-FB-002 | B5: SC-01 | C5: FCL Buying | D5: Add new Buying | E5: UI | F5: Biểu tượng thông tin (i) cạnh Place of Receipt (Empty), Place of Loading/Unloading, Place of Return (Empty) hiển thị chú thích | G5: Đăng nhập role có quyền Add | H5: Không cần dữ liệu | I5: 1. Vào Pricing > FCL Pricing > FCL Buying 2. Nhấn nút Add New Buying để mở form tạo mới 3. Rê chuột vào biểu tượng (i) 4. Đọc chú thích 5. Đối chiếu với nghiệp vụ | J5: Hiển thị tooltip giải thích đúng nội dung và không bị cắt chữ | L5: Pass | M5: Low
A6: ="TC-FB-"&TEXT(ROW()-3,"000") -> TC-FB-003 | B6: SC-01 | C6: FCL Buying | D6: Add new Buying | E6: UI | F6: Giá trị mặc định khi mở form tạo mới | G6: Đăng nhập role có quyền Add | H6: Không cần dữ liệu | I6: 1. Vào Pricing > FCL Pricing > FCL Buying 2. Nhấn nút Add New Buying để mở form tạo mới 3. Quan sát giá trị mặc định các trường 4. Không nhập gì 5. Ghi lại giá trị từng trường | J6: Service Type = Transportation; Currency = giá trị đang tick Default trong Catalogue > Currency; VAT Rate = mã VATRate có hiệu lực theo ngày hiện tại trong Accounting > Parameters; Status bật; Include VAT, Dangerous Goods, Refrigerated Goods không tick; các trường còn lại trống và hiển thị placeholder | L6: Pass | M6: Medium
A7: ="TC-FB-"&TEXT(ROW()-3,"000") -> TC-FB-004 | B7: SC-01 | C7: FCL Buying | D7: Add new Buying | E7: UI | F7: Thứ tự di chuyển bằng phím Tab hợp lý | G7: Đăng nhập role có quyền Add | H7: Không cần dữ liệu | I7: 1. Vào Pricing > FCL Pricing > FCL Buying 2. Nhấn nút Add New Buying để mở form tạo mới 3. Bấm vào ô Supplier 4. Nhấn Tab liên tiếp qua các trường 5. Ghi lại thứ tự focus | J7: Focus di chuyển lần lượt theo bố cục form (trái sang phải, trên xuống dưới), không nhảy lung tung và không rơi ra ngoài form | L7: Pass | M7: Low
A8: ="TC-FB-"&TEXT(ROW()-3,"000") -> TC-FB-005 | B8: SC-01 | C8: FCL Buying | D8: Add new Buying | E8: UI | F8: Mở lại form sau khi lưu thì form trở về mặc định | G8: Đăng nhập role có quyền Add | H8: Tạo 1 bản ghi rồi mở form tạo mới lần nữa | I8: 1. Vào Pricing > FCL Pricing > FCL Buying 2. Nhấn nút Add New Buying để mở form tạo mới 3. Chọn Supplier, Place From, Place To, Mode Of Transport, Weight Range, Container Type; nhập Price (Service Type, Currency, VAT Rate giữ mặc định) 4. Lưu; nhấn nút thêm mới lần nữa 5. Quan sát form | J8: Form trở về trạng thái mặc định, không giữ dữ liệu của lần trước | L8: Pass | M8: Medium
A9: ="TC-FB-"&TEXT(ROW()-3,"000") -> TC-FB-006 | B9: SC-01 | C9: FCL Buying | D9: Add new Buying | E9: UI | F9: VAT Rate mặc định lấy theo mã VATRate của ngày hiện tại | G9: Đăng nhập role có quyền Add; có quyền xem màn hình Accounting > Parameters | H9: Ngày hiện tại | I9: 1. Mở màn hình Accounting > Parameters, ghi lại mã VATRate có hiệu lực ở ngày hôm nay 2. Vào Pricing > FCL Pricing > FCL Buying 3. Nhấn nút Add New Buying để mở form tạo mới 4. Đối chiếu giá trị VAT Rate mặc định trên form | J9: VAT Rate mặc định bằng mã VATRate có hiệu lực theo ngày hiện tại trong Accounting > Parameters | L9: Pass | M9: Medium
A10: ="TC-FB-"&TEXT(ROW()-3,"000") -> TC-FB-007 | B10: SC-01 | C10: FCL Buying | D10: Add new Buying | E10: UI | F10: Currency mặc định theo giá trị tick Default ở Catalogue > Currency | G10: Đăng nhập role có quyền Add; có quyền xem màn hình Catalogue > Currency | H10: Currency đang tick Default | I10: 1. Mở màn hình Catalogue > Currency, ghi lại loại tiền đang tick Default 2. Vào Pricing > FCL Pricing > FCL Buying 3. Nhấn nút Add New Buying để mở form tạo mới 4. Đối chiếu giá trị Currency mặc định trên form | J10: Currency mặc định trên form là loại tiền đang tick Default ở Catalogue > Currency | L10: Pass | M10: Medium
A11: ="TC-FB-"&TEXT(ROW()-3,"000") -> TC-FB-008 | B11: SC-02 | C11: FCL Buying | D11: Add new Buying | E11: Positive | F11: Tạo giá mua FCL thành công chỉ với các trường bắt buộc | G11: Đăng nhập role có quyền Add | H11: Chỉ điền trường bắt buộc | I11: 1. Vào Pricing > FCL Pricing > FCL Buying 2. Nhấn nút Add New Buying để mở form tạo mới 3. Chọn Supplier, Place From, Place To, Mode Of Transport, Weight Range, Container Type; nhập Price (Service Type, Currency, VAT Rate giữ mặc định) 4. Nhấn Save 5. Kiểm tra bản ghi mới trong danh sách (tab Updating) và mở lại để đối chiếu dữ liệu | J11: Lưu thành công, hiển thị thông báo "New data added" màu xanh, form đóng; bản ghi mới xuất hiện trong danh sách với dữ liệu đúng như đã nhập | L11: Pass | M11: High
A12: ="TC-FB-"&TEXT(ROW()-3,"000") -> TC-FB-009 | B12: SC-02 | C12: FCL Buying | D12: Add new Buying | E12: Positive | F12: Tạo giá mua FCL thành công với đầy đủ tất cả các trường | G12: Đăng nhập role có quyền Add | H12: Điền đủ tất cả trường | I12: 1. Vào Pricing > FCL Pricing > FCL Buying 2. Nhấn nút Add New Buying để mở form tạo mới 3. Điền tất cả trường: Supplier, Place From, Place To, Place of Receipt, Place of Loading/Unloading, Place of Return, Service Type, Customer, Mode Of Transport, Weight Range, Container Type, Contract No, Weekdays, Currency, Price, VAT Rate, Include VAT, Project Name, Return Assoc Freight Percent, Canceled Freight Percent, Note, Dangerous Goods, Refrigerated Goods 4. Nhấn Save 5. Kiểm tra bản ghi mới trong danh sách (tab Updating) và mở lại để đối chiếu dữ liệu | J12: Lưu thành công, hiển thị thông báo "New data added" màu xanh, form đóng; bản ghi mới xuất hiện trong danh sách với dữ liệu đúng như đã nhập | L12: Pass | M12: High
A13: ="TC-FB-"&TEXT(ROW()-3,"000") -> TC-FB-010 | B13: SC-02 | C13: FCL Buying | D13: Add new Buying | E13: Positive | F13: Tạo giá mua FCL chỉ với các trường bắt buộc lưu thành công và giữ form cho nhập tiếp | G13: Đăng nhập role có quyền Add | H13: Chỉ điền trường bắt buộc | I13: 1. Vào Pricing > FCL Pricing > FCL Buying 2. Nhấn nút Add New Buying để mở form tạo mới 3. Chọn Supplier, Place From, Place To, Mode Of Transport, Weight Range, Container Type; nhập Price (Service Type, Currency, VAT Rate giữ mặc định) 4. Nhấn Save 5. Kiểm tra bản ghi mới trong danh sách (tab Updating) và mở lại để đối chiếu dữ liệu | J13: Lưu thành công, hiển thị thông báo "New data added" màu xanh; form vẫn mở để nhập bản ghi mới, để trống các trường Weight Range, Container Type, Weekdays, Return Assoc Freight Percent, Canceled Freight Percent, Note; Dangerous Goods, Refrigerated Goods không tick; bản ghi vừa lưu có trong danh sách | L13: Pass | M13: Medium
A14: ="TC-FB-"&TEXT(ROW()-3,"000") -> TC-FB-011 | B14: SC-02 | C14: FCL Buying | D14: Add new Buying | E14: UI | F14: Nút Cancel đóng form và không lưu dữ liệu | G14: Đăng nhập role có quyền Add | H14: Điền vài trường bất kỳ | I14: 1. Vào Pricing > FCL Pricing > FCL Buying 2. Nhấn nút Add New Buying để mở form tạo mới 3. Điền vài trường (Supplier, Place From, Price) 4. Nhấn Cancel 5. Kiểm tra danh sách | J14: Form đóng, Không phát sinh bản ghi mới trong danh sách | L14: Pass | M14: Medium
A15: ="TC-FB-"&TEXT(ROW()-3,"000") -> TC-FB-012 | B15: SC-02 | C15: FCL Buying | D15: Add new Buying | E15: UI | F15: Nút đóng (X) góc trên phải đóng form và không lưu dữ liệu | G15: Đăng nhập role có quyền Add | H15: Điền vài trường bất kỳ | I15: 1. Vào Pricing > FCL Pricing > FCL Buying 2. Nhấn nút Add New Buying để mở form tạo mới 3. Điền vài trường (Supplier, Place From, Price) 4. Nhấn nút đóng đỏ ở góc trên phải form 5. Kiểm tra danh sách | J15: Form đóng, Không phát sinh bản ghi mới trong danh sách | L15: Pass | M15: Low
... A29: ="TC-FB-"&TEXT(ROW()-3,"000") -> TC-FB-026 | B29: SC-04 | C29: FCL Buying | D29: Add new Buying | E29: Validation | F29: Ô Price không nhận ký tự chữ | G29: Đăng nhập role có quyền Add | H29: Price = abc | I29: 1. Vào Pricing > FCL Pricing > FCL Buying 2. Nhấn nút Add New Buying để mở form tạo mới 3. Chọn Supplier, Place From, Place To, Mode Of Transport, Weight Range, Container Type; nhập Price = abc (Service Type, Currency, VAT Rate giữ mặc định) 4. Quan sát ô Price rồi nhấn Save 5. Kiểm tra giá trị ô Price | J29: Ô Price không nhận ký tự chữ; không lưu bản ghi với giá trị sai | L29: Pass | M29: Medium
A30: ="TC-FB-"&TEXT(ROW()-3,"000") -> TC-FB-027 | B30: SC-04 | C30: FCL Buying | D30: Add new Buying | E30: Boundary | F30: Không lưu được khi Price là số âm | G30: Đăng nhập role có quyền Add | H30: Price = -1500000 | I30: 1. Vào Pricing > FCL Pricing > FCL Buying 2. Nhấn nút Add New Buying để mở form tạo mới 3. Chọn Supplier, Place From, Place To, Mode Of Transport, Weight Range, Container Type; nhập Price = -1500000 (Service Type, Currency, VAT Rate giữ mặc định) 4. Nhấn Save 5. Quan sát thông báo lỗi và danh sách | J30: Không lưu được; báo lỗi Price không hợp lệ; Không phát sinh bản ghi mới trong danh sách | K30: Lưu thành công, hiển thị thông báo "New data added" màu xanh, form đóng; bản ghi mới xuất hiện trong danh sách với dữ liệu đúng như đã nhập | L30: Fail | M30: High | N30: BUG-001
A31: ="TC-FB-"&TEXT(ROW()-3,"000") -> TC-FB-028 | B31: SC-04 | C31: FCL Buying | D31: Add new Buying | E31: Boundary | F31: Lưu với Price = 0 (giá trị biên) | G31: Đăng nhập role có quyền Add | H31: Price = 0 | I31: 1. Vào Pricing > FCL Pricing > FCL Buying 2. Nhấn nút Add New Buying để mở form tạo mới 3. Chọn Supplier, Place From, Place To, Mode Of Transport, Weight Range, Container Type; nhập Price = 0 (Service Type, Currency, VAT Rate giữ mặc định) 4. Nhấn Save 5. Quan sát kết quả | J31: Hệ thống xử lý đúng quy tắc nghiệp vụ (từ chối hoặc chấp nhận giá 0) | K31: Lưu thành công, hiển thị thông báo "New data added" màu xanh, form đóng; bản ghi mới xuất hiện trong danh sách với tất cả các trường dữ liệu đúng như đã nhập trừ trường Price NULL | L31: Fail | M31: High | N31: BUG-001 | Q31: CONFIRM với BA: giá = 0 có hợp lệ không? Trường Price bắt buộc nhưng khi nhập 0 kết quả thực hiện lại là NULL => Price = 0 không hợp lệ
A32: ="TC-FB-"&TEXT(ROW()-3,"000") -> TC-FB-029 | B32: SC-04 | C32: FCL Buying | D32: Add new Buying | E32: Boundary | F32: Không lưu được khi VAT Rate là số âm | G32: Đăng nhập role có quyền Add | H32: VAT Rate = -1 | I32: 1. Vào Pricing > FCL Pricing > FCL Buying 2. Nhấn nút Add New Buying để mở form tạo mới 3. Chọn Supplier, Place From, Place To, Mode Of Transport, Weight Range, Container Type; nhập Price (Service Type, Currency, VAT Rate giữ mặc định); nhập VAT Rate = -1 4. Nhấn Save 5. Quan sát thông báo lỗi và danh sách | J32: Không lưu được; báo lỗi VAT Rate không hợp lệ; Không phát sinh bản ghi mới trong danh sách | K32: Lưu thành công, hiển thị thông báo "New data added" màu xanh, form đóng; bản ghi mới xuất hiện trong danh sách với dữ liệu đúng như đã nhập | L32: Fail | M32: Medium | N32: BUG-002
A33: ="TC-FB-"&TEXT(ROW()-3,"000") -> TC-FB-030 | B33: SC-04 | C33: FCL Buying | D33: Add new Buying | E33: Boundary | F33: Không lưu được khi VAT Rate lớn hơn 100 | G33: Đăng nhập role có quyền Add | H33: VAT Rate = 101 | I33: 1. Vào Pricing > FCL Pricing > FCL Buying 2. Nhấn nút Add New Buying để mở form tạo mới 3. Chọn Supplier, Place From, Place To, Mode Of Transport, Weight Range, Container Type; nhập Price (Service Type, Currency, VAT Rate giữ mặc định); nhập VAT Rate = 101 4. Nhấn Save 5. Quan sát thông báo lỗi và danh sách | J33: Không lưu được; báo lỗi VAT Rate không hợp lệ; Không phát sinh bản ghi mới trong danh sách | K33: Lưu thành công, hiển thị thông báo "New data added" màu xanh, form đóng; bản ghi mới xuất hiện trong danh sách với dữ liệu đúng như đã nhập | L33: Fail | M33: Medium | N33: BUG-002
A34: ="TC-FB-"&TEXT(ROW()-3,"000") -> TC-FB-031 | B34: SC-04 | C34: FCL Buying | D34: Add new Buying | E34: UI | F34: Nút tăng/giảm (mũi tên) của ô VAT Rate và Price hoạt động đúng | G34: Đăng nhập role có quyền Add | H34: Dùng mũi tên và bàn phím | I34: 1. Vào Pricing > FCL Pricing > FCL Buying 2. Nhấn nút Add New Buying để mở form tạo mới 3. Bấm mũi tên lên/xuống ở VAT Rate và Price 4. Bấm giữ mũi tên và dùng phím lên/xuống 5. Ghi lại giá trị sau mỗi lần bấm | J34: Giá trị tăng/giảm đúng bước; không cho giảm xuống dưới giới hạn cho phép; không nhảy giá trị bất thường | K34: VAT Rate và Price đều giảm được xuống giá trị âm. VAT Rate tăng được hơn 100 | L34: Fail | M34: Low | N34: BUG-003
A35: ="TC-FB-"&TEXT(ROW()-3,"000") -> TC-FB-032 | B35: SC-04 | C35: FCL Buying | D35: Add new Buying | E35: Positive | F35: Nhập Freight Percent thập phân dùng dấu chấm | G35: Đăng nhập role có quyền Add | H35: Return Assoc Freight Percent, Canceled Freight Percent = 9.5;9.5 | I35: 1. Vào Pricing > FCL Pricing > FCL Buying 2. Nhấn nút Add New Buying để mở form tạo mới 3. Chọn Supplier, Place From, Place To, Mode Of Transport, Weight Range, Container Type; nhập Price (Service Type, Currency, VAT Rate giữ mặc định); nhập Return Assoc Freight Percent, Canceled Freight Percent = 9.5;9.5 4. Nhấn Save 5. Kiểm tra bản ghi mới trong danh sách (tab Updating) và mở lại để đối chiếu dữ liệu | J35: Lưu thành công, hiển thị thông báo thành công, form đóng; bản ghi mới xuất hiện trong danh sách với dữ liệu đúng như đã nhập | L35: Pass | M35: Medium
A36: ="TC-FB-"&TEXT(ROW()-3,"000") -> TC-FB-033 | B36: SC-04 | C36: FCL Buying | D36: Add new Buying | E36: Validation | F36: Không lưu được khi Freight Percent dùng dấu phẩy | G36: Đăng nhập role có quyền Add | H36: Return Assoc Freight Percent, Canceled Freight Percent = "9,5;9,5" | I36: 1. Vào Pricing > FCL Pricing > FCL Buying 2. Nhấn nút Add New Buying để mở form tạo mới 3. Chọn Supplier, Place From, Place To, Mode Of Transport, Weight Range, Container Type; nhập Price (Service Type, Currency, VAT Rate giữ mặc định); nhập Return Assoc Freight Percent, Canceled Freight Percent = 9,5;9,5 4. Nhấn Save 5. Quan sát thông báo lỗi và danh sách | J36: Không lưu được; báo lỗi định dạng; Không phát sinh bản ghi mới trong danh sách | K36: Lưu được khi chỉ nhập Canceled Freight Percent không nhập Return Assoc Freight Percent | L36: Fail | M36: Medium | N36: BUG-004
A37: ="TC-FB-"&TEXT(ROW()-3,"000") -> TC-FB-034 | B37: SC-04 | C37: FCL Buying | D37: Add new Buying | E37: Validation | F37: Không lưu được khi Freight Percent chứa ký tự chữ | G37: Đăng nhập role có quyền Add | H37: nhập cả Return Assoc Freight Percent, Canceled Freight Percent = "abc;abc" | I37: 1. Vào Pricing > FCL Pricing > FCL Buying 2. Nhấn nút Add New Buying để mở form tạo mới 3. Chọn Supplier, Place From, Place To, Mode Of Transport, Weight Range, Container Type; nhập Price (Service Type, Currency, VAT Rate giữ mặc định); nhập cả Return Assoc Freight Percent, Canceled Freight Percent = abc;abc 4. Nhấn Save 5. Quan sát thông báo lỗi và danh sách | J37: Không lưu được; báo lỗi định dạng; Không phát sinh bản ghi mới trong danh sách | K37: Lưu được khi chỉ nhập Canceled Freight Percent không nhập Return Assoc Freight Percent | L37: Fail | M37: Medium | N37: BUG-004
A38: ="TC-FB-"&TEXT(ROW()-3,"000") -> TC-FB-035 | B38: SC-04 | C38: FCL Buying | D38: Add new Buying | E38: Boundary | F38: Không lưu được khi Freight Percent là số âm hoặc lớn hơn 100 | G38: Đăng nhập role có quyền Add | H38: nhập cả Return Assoc Freight Percent, Canceled Freight Percent = "-1;9" và "101;9" (thử lần lượt) | I38: 1. Vào Pricing > FCL Pricing > FCL Buying 2. Nhấn nút Add New Buying để mở form tạo mới 3. Chọn Supplier, Place From, Place To, Mode Of Transport, Weight Range, Container Type; nhập Price (Service Type, Currency, VAT Rate giữ mặc định); nhập cả Return Assoc Freight Percent, Canceled Freight Percent = -1;9 rồi thử 101;9 4. Nhấn Save 5. Quan sát thông báo lỗi và danh sách | J38: Không lưu được; báo lỗi định dạng; Không phát sinh bản ghi mới trong danh sách | K38: Lưu được khi chỉ nhập Canceled Freight Percent không nhập Return Assoc Freight Percent | L38: Fail | M38: Medium | N38: BUG-004
A39: ="TC-FB-"&TEXT(ROW()-3,"000") -> TC-FB-036 | B39: SC-04 | C39: FCL Buying | D39: Add new Buying | E39: Positive | F39: Lưu đúng Note và Project Name chứa tiếng Việt có dấu và ký tự đặc biệt | G39: Đăng nhập role có quyền Add | H39: Note = "Ghi chú: hàng lạnh & dễ vỡ (10%)"; Project Name = "Dự án Ánh Dương #1" | I39: 1. Vào Pricing > FCL Pricing > FCL Buying 2. Nhấn nút Add New Buying để mở form tạo mới 3. Chọn Supplier, Place From, Place To, Mode Of Transport, Weight Range, Container Type; nhập Price (Service Type, Currency, VAT Rate giữ mặc định); nhập Note và Project Name theo Test data 4. Nhấn Save 5. Mở lại bản ghi và đối chiếu | J39: Lưu thành công; Note và Project Name hiển thị lại đúng, không lỗi font, không mất ký tự | L39: Pass | M39: Low
A40: ="TC-FB-"&TEXT(ROW()-3,"000") -> TC-FB-037 | B40: SC-04 | C40: FCL Buying | D40: Add new Buying | E40: Validation | F40: Chỉ nhập khoảng trắng vào Project Name và Note | G40: Đăng nhập role có quyền Add | H40: Project Name = " ", Note = " " | I40: 1. Vào Pricing > FCL Pricing > FCL Buying 2. Nhấn nút Add New Buying để mở form tạo mới 3. Chọn Supplier, Place From, Place To, Mode Of Transport, Weight Range, Container Type; nhập Price (Service Type, Currency, VAT Rate giữ mặc định); nhập chỉ khoảng trắng vào Project Name và Note 4. Nhấn Save 5. Mở lại bản ghi | J40: Hệ thống tự cắt khoảng trắng (trường để trống) hoặc báo lỗi rõ ràng; không lưu chuỗi toàn khoảng trắng | K40: Lưu thành công, hiển thị thông báo "New data added" màu xanh, form đóng; bản ghi mới xuất hiện trong danh sách với dữ liệu đúng như đã nhập | L40: Fail | M40: Low | N40: BUG-005
A41: ="TC-FB-"&TEXT(ROW()-3,"000") -> TC-FB-038 | B41: SC-04 | C41: FCL Buying | D41: Add new Buying | E41: Positive | F41: Note nhiều dòng lưu và hiển thị đúng | G41: Đăng nhập role có quyền Add | H41: Note gồm 3 dòng (xuống dòng bằng Enter) | I41: 1. Vào Pricing > FCL Pricing > FCL Buying 2. Nhấn nút Add New Buying để mở form tạo mới 3. Chọn Supplier, Place From, Place To, Mode Of Transport, Weight Range, Container Type; nhập Price (Service Type, Currency, VAT Rate giữ mặc định); nhập Note 3 dòng 4. Nhấn Save 5. Mở lại bản ghi | J41: Lưu thành công; Note giữ nguyên các dòng khi mở lại | K41: Lưu thành công, hiển thị thông báo "New data added" màu xanh, form đóng; bản ghi mới xuất hiện trong danh sách với dữ liệu đúng như đã nhập | L41: Pass | M41: Low
A42: ="TC-FB-"&TEXT(ROW()-3,"000") -> TC-FB-039 | B42: SC-04 | C42: FCL Buying | D42: Add new Buying | E42: Boundary | F42: Kiểm tra giới hạn độ dài Project Name và Note | G42: Đăng nhập role có quyền Add | H42: Project Name 300 ký tự, Note 5000 ký tự | I42: 1. Vào Pricing > FCL Pricing > FCL Buying 2. Nhấn nút Add New Buying để mở form tạo mới 3. Chọn Supplier, Place From, Place To, Mode Of Transport, Weight Range, Container Type; nhập Price (Service Type, Currency, VAT Rate giữ mặc định); nhập Project Name 300 ký tự, Note 5000 ký tự 4. Nhấn Save 5. Quan sát kết quả | J42: Nếu vượt giới hạn: báo lỗi màu đỏ nêu rõ trường và độ dài tối đa, không hiện 'New data added'. Nếu hợp lệ: thông báo màu thành công, form đóng, bản ghi xuất hiện trong danh sách | K42: Trường Project Name 300 ký tự báo, hiển thị thông báo New data added nhưng màu đỏ, form tạo mới giữ nguyên, danh sách không hiện thị dữ liệu mới | L42: Fail | M42: Low | N42: BUG-006 | Q42: CONFORM: Độ dài tối đa của Project Name?
A43: ="TC-FB-"&TEXT(ROW()-3,"000") -> TC-FB-040 | B43: SC-05 | C43: FCL Buying | D43: Add new Buying | E43: UI | F43: Dropdown Supplier, Place From, Place To, Place of Receipt (Empty), Place of Loading/Unloading, Place of Return (Empty), Service Type, Customer, Mode Of Transport, Weight Range, Container Type, Contract No, Weekdays, Currency hỗ trợ gõ để tìm kiếm | G43: Đăng nhập role có quyền Add | H43: Gõ 1 phần tên nhà cung cấp | I43: 1. Vào Pricing > FCL Pricing > FCL Buying 2. Nhấn nút Add New Buying để mở form tạo mới 3. Bấm vào dropdown Supplier, gõ 1 phần dữ liệu cần tìm kiếm. Áp dụng lần lượt cho các dropdown 4. Quan sát danh sách lọc 5. Chọn 1 kết quả | J43: Danh sách lọc theo từ khóa; chọn được giá trị và hiển thị đúng trong ô | L43: Pass | M43: Low
A44: ="TC-FB-"&TEXT(ROW()-3,"000") -> TC-FB-041 | B44: SC-05 | C44: FCL Buying | D44: Add new Buying | E44: Integration | F44: Danh sách Contract No phụ thuộc vào Customer đã chọn | G44: Đăng nhập role có quyền Add | H44: Chọn Customer rồi mở Contract No | I44: 1. Vào Pricing > FCL Pricing > FCL Buying 2. Nhấn nút Add New Buying để mở form tạo mới 3. Chọn 1 Customer 4. Mở dropdown Contract No 5. Đối chiếu hợp đồng với Customer | J44: Contract No chỉ hiển thị các hợp đồng của Customer đã chọn | L44: Pass | M44: Medium
A45: ="TC-FB-"&TEXT(ROW()-3,"000") -> TC-FB-042 | B45: SC-05 | C45: FCL Buying | D45: Add new Buying | E45: Positive | F45: Chọn nhiều Weekdays và lưu đúng | G45: Đăng nhập role có quyền Add | H45: Weekdays: Monday, Tuesday | I45: 1. Vào Pricing > FCL Pricing > FCL Buying 2. Nhấn nút Add New Buying để mở form tạo mới 3. Chọn Supplier, Place From, Place To, Mode Of Transport, Weight Range, Container Type; nhập Price (Service Type, Currency, VAT Rate giữ mặc định); chọn Weekdays = Monday và Tuesday 4. Nhấn Save 5. Xem cột Weekdays trong danh sách | J45: Lưu thành công; cột Weekdays hiển thị Monday;Tuesday | L45: Pass | M45: Medium
A46: ="TC-FB-"&TEXT(ROW()-3,"000") -> TC-FB-043 | B46: SC-05 | C46: FCL Buying | D46: Add new Buying | E46: UI | F46: Nút + cạnh Place of Loading/Unloading mở popup chọn nhiều giá trị | G46: Đăng nhập role có quyền Add | H46: Chọn 2-3 giá trị trong popup | I46: 1. Vào Pricing > FCL Pricing > FCL Buying 2. Nhấn nút Add New Buying để mở form tạo mới 3. Chọn Supplier, Place From, Place To, Mode Of Transport, Weight Range, Container Type; nhập Price (Service Type, Currency, VAT Rate giữ mặc định) 4. Bấm nút + cạnh Place of Loading/Unloading, chọn 2-3 giá trị trong danh sách, xác nhận popup, nhấn Save 5. Mở lại bản ghi và kiểm tra trường Place of Loading/Unloading | J46: Popup mở đúng và cho chọn nhiều giá trị; các giá trị đã chọn hiển thị trong trường; lưu thành công và mở lại đủ các giá trị | L46: Pass | M46: Low
A47: ="TC-FB-"&TEXT(ROW()-3,"000") -> TC-FB-044 | B47: SC-05 | C47: FCL Buying | D47: Add new Buying | E47: UI | F47: Nút + cạnh Place of Return (Empty) mở popup chọn nhiều giá trị | G47: Đăng nhập role có quyền Add | H47: Chọn 2-3 giá trị trong popup | I47: 1. Vào Pricing > FCL Pricing > FCL Buying 2. Nhấn nút Add New Buying để mở form tạo mới 3. Chọn Supplier, Place From, Place To, Mode Of Transport, Weight Range, Container Type; nhập Price (Service Type, Currency, VAT Rate giữ mặc định) 4. Bấm nút + cạnh Place of Return (Empty), chọn 2-3 giá trị trong danh sách, xác nhận popup, nhấn Save 5. Mở lại bản ghi và kiểm tra trường Place of Return | J47: Popup mở đúng và cho chọn nhiều giá trị; các giá trị đã chọn hiển thị trong trường; lưu thành công và mở lại đủ các giá trị | L47: Pass | M47: Low
A48: ="TC-FB-"&TEXT(ROW()-3,"000") -> TC-FB-045 | B48: SC-05 | C48: FCL Buying | D48: Add new Buying | E48: UI | F48: Nút + cạnh Place of Receipt (Empty) bị vô hiệu hóa vì trường chỉ chọn một giá trị | G48: Đăng nhập role có quyền Add | H48: Không cần dữ liệu | I48: 1. Vào Pricing > FCL Pricing > FCL Buying 2. Nhấn nút Add New Buying để mở form tạo mới 3. Quan sát nút + cạnh Place of Receipt (Empty) 4. Bấm vào nút + đó 5. Quan sát phản hồi của giao diện | J48: Nút hiển thị màu nhạt (disabled); bấm vào không mở popup và không có phản hồi nào | L48: Pass | M48: Low
A49: ="TC-FB-"&TEXT(ROW()-3,"000") -> TC-FB-046 | B49: SC-06 | C49: FCL Buying | D49: Add new Buying | E49: Integration | F49: Effective On và Expiry On của bản ghi lấy đúng theo hợp đồng đã chọn | G49: Đăng nhập role có quyền Add | H49: Contract No có cả ngày hiệu lực và ngày hết hạn | I49: 1. Vào Pricing > FCL Pricing > FCL Buying 2. Nhấn nút Add New Buying để mở form tạo mới 3. Chọn Supplier, Place From, Place To, Mode Of Transport, Weight Range, Container Type; nhập Price (Service Type, Currency, VAT Rate giữ mặc định); chọn Contract No (ghi lạiEffective On, Expiry On của hợp đồng đang chọn) 4. Nhấn Save 5. Kiểm tra bản ghi mới trong danh sách (tab Updating) và xem cột Effective On, Expiry On của bản ghi vừa tạo | J49: Effective On và Expiry On của bản ghi khớp đúng Effective On và Expiry On của hợp đồng đã chọn | L49: Pass | M49: High
A50: ="TC-FB-"&TEXT(ROW()-3,"000") -> TC-FB-047 | B50: SC-07 | C50: FCL Buying | D50: Bản ghi ở tab Updating | E50: Integration | F50: Bản ghi mới vào đúng tab Updating và bộ đếm tăng 1 | G50: Đăng nhập role có quyền Add | H50: Tạo bản ghi mới | I50: 1. Vào Pricing > FCL Pricing > FCL Buying 2. Nhấn nút Add New Buying để mở form tạo mới 3. Ghi lại số ở tab Updating trước khi tạo; Chọn Supplier, Place From, Place To, Mode Of Transport, Weight Range, Container Type; nhập Price (Service Type, Currency, VAT Rate giữ mặc định) 4. Nhấn Save 5. So sánh số ở tab Updating trước và sau | J50: Bản ghi mới xuất hiện trong tab Updating; số đếm các tab thay đổi đúng | L50: Pass | M50: Medium
A51: ="TC-FB-"&TEXT(ROW()-3,"000") -> TC-FB-048 | B51: SC-07 | C51: FCL Buying | D51: Bản ghi ở tab Updating | E51: UI | F51: Menu 3 chấm ở tab Updating có đúng các thao tác của trạng thái này | G51: Đăng nhập role có quyền RequestApproval, Update, Delete; có ít nhất 1 bản ghi ở tab Updating đã chọn Contract No | H51: Không cần dữ liệu | I51: 1. Vào Pricing > FCL Pricing > FCL Buying 2. Mở tab Updating 3. rê chuột vào nút 3 chấm của bản ghi 4. Ghi lại các mục trong menu | J51: Menu hiện khi rê chuột và có Send request, Edit, Delete (Dollar nằm ngoài phạm vi) | L51: Pass | M51: Medium
A52: ="TC-FB-"&TEXT(ROW()-3,"000") -> TC-FB-049 | B52: SC-07 | C52: FCL Buying | D52: Edit ở tab Updating | E52: Positive | F52: Edit bản ghi ở tab Updating và lưu thành công | G52: Đăng nhập role có quyền Update; có ít nhất 1 bản ghi ở tab Updating chỉ lưu các trường bắt buộc | H52: Sửa tất cả các trường bắt buộc | I52: 1. Vào Pricing > FCL Pricing > FCL Buying 2. Mở tab Updating, rê chuột vào nút 3 chấm của bản ghi, chọn Edit 3. Sửa Supplier, Place From, Place To, Mode Of Transport, Weight Range, Container Type; Price; Currency, VAT Rate sang giá trị khác 4. Nhấn Save 5. Xem lại bản ghi trong danh sách và mở lại Edit | J52: Lưu thành công; giá trị mới hiển thị đúng; bản ghi vẫn ở tab Updating | L52: Pass | M52: High
A53: ="TC-FB-"&TEXT(ROW()-3,"000") -> TC-FB-050 | B53: SC-07 | C53: FCL Buying | D53: Edit tab Updating | E53: Validation | F53: Edit không lưu được khi xóa trường bắt buộc | G53: Đăng nhập role có quyền Update; Có ít nhất 1 bản ghi ở tab Updating đã chọn Contract No | H53: Xóa giá trị Price | I53: 1. Vào Pricing > FCL Pricing > FCL Buying 2. Mở tab Updating, rê chuột vào nút 3 chấm của bản ghi, chọn Edit 3. Xóa giá trị trường bắt buộc (ví dụ Price) 4. Nhấn Save 5. Quan sát thông báo lỗi và dữ liệu bản ghi | J53: Không lưu được; trường bị xóa được đánh dấu lỗi; dữ liệu cũ của bản ghi không bị thay đổi | L53: Pass | M53: High
A54: ="TC-FB-"&TEXT(ROW()-3,"000") -> TC-FB-051 | B54: SC-07 | C54: FCL Buying | D54: Edit ở tab Updating | E54: UI | F54: Hủy sửa thì không lưu thay đổi | G54: Đăng nhập role có quyền Update; có ít nhất 1 bản ghi ở tab Updating đã chọn Contract No | H54: Sửa vài trường rồi Cancel | I54: 1. Vào Pricing > FCL Pricing > FCL Buying 2. Mở tab Updating, rê chuột vào nút 3 chấm của bản ghi, chọn Edit 3. Sửa vài trường (Price, Note) 4. Nhấn Cancel hoặc nút đóng 5. Mở lại Edit và đối chiếu dữ liệu | J54: Form đóng; dữ liệu bản ghi giữ nguyên như trước khi sửa | L54: Pass | M54: Medium
...

Sheet Bug Report
A1: BUG REPORT
A3: Bug ID | B3: Tiêu đề | C3: Chức năng | D3: Môi trường | E3: Build / Version | F3: Các bước tái hiện | G3: Kết quả thực tế | H3: Kết quả mong đợi | I3: Severity | J3: Priority | K3: Trạng thái | L3: Người báo | M3: Ngày báo | N3: Người xử lý | O3: TC liên quan | P3: Đính kèm (ảnh/log/video) | Q3: Ghi chú
A4: BUG-001 | B4: Cho phép lưu Price là số âm và số 0 | C4: Add new Buying | F4: 1. Vào Pricing > FCL Pricing > FCL Buying 2. Nhấn nút Add New Buying để mở form tạo mới 3. Chọn Supplier, Place From, Place To, Mode Of Transport, Weight Range, Container Type; nhập Price lần 1 (-1500000), lần 2 (0) (Service Type, Currency, VAT Rate giữ mặc định) 4. Nhấn Save 5. Quan sát thông báo lỗi và danh sách | G4: Lưu thành công, hiển thị thông báo "New data added" màu xanh, form đóng; bản ghi mới xuất hiện trong danh sách với dữ liệu đúng như đã nhập | H4: Không lưu được; báo lỗi Price không hợp lệ; Không phát sinh bản ghi mới trong danh sách | I4: Major | J4: High | K4: Open | O4: TC-FB-027, TC-FB-028
A5: BUG-002 | B5: Cho phép lưu VAT Rate là số âm hoặc lớn hơn 100 | C5: Add new Buying | F5: 1. Vào Pricing > FCL Pricing > FCL Buying 2. Nhấn nút Add New Buying để mở form tạo mới 3. Chọn Supplier, Place From, Place To, Mode Of Transport, Weight Range, Container Type; nhập Price (Service Type, Currency, VAT Rate giữ mặc định); lần 1 nhập -1, lần 2 nhập 101 4. Nhấn Save 5. Quan sát thông báo lỗi và danh sách | G5: Lưu thành công, hiển thị thông báo "New data added" màu xanh, form đóng; bản ghi mới xuất hiện trong danh sách với dữ liệu đúng như đã nhập | H5: Không lưu được; báo lỗi VAT Rate không hợp lệ; Không phát sinh bản ghi mới trong danh sách | I5: Major | J5: Medium | K5: Open | O5: TC-FB-029, TC-FB-030
A6: BUG-003 | B6: Nút tăng/giảm (mũi tên) của ô VAT Rate và Price vượt giới hạn cho phép | C6: Add new Buying | F6: 1. Vào Pricing > FCL Pricing > FCL Buying 2. Nhấn nút Add New Buying để mở form tạo mới 3. Bấm mũi tên lên/xuống ở VAT Rate và Price 4. Bấm giữ mũi tên và dùng phím lên/xuống 5. Ghi lại giá trị sau mỗi lần bấm | G6: VAT Rate và Price đều giảm được xuống giá trị âm. VAT Rate tăng được hơn 100 | H6: Giá trị tăng/giảm đúng bước; không cho giảm xuống dưới giới hạn cho phép; không nhảy giá trị bất thường | I6: Minor | J6: Low | K6: Open | O6: TC-FB-031
A7: BUG-004 | B7: Cho phép lưu được khi Freight Percent dùng dấu phẩy, chứa ký tự chữ, số âm hoặc lớn hơn 100 | C7: Add new Buying | F7: 1. Vào Pricing > FCL Pricing > FCL Buying 2. Nhấn nút Add New Buying để mở form tạo mới 3. Chọn Supplier, Place From, Place To, Mode Of Transport, Weight Range, Container Type; nhập Price (Service Type, Currency, VAT Rate giữ mặc định); nhập Canceled Freight Percent lần 1 (9,5;9,5), 2 (abc;abc), 3 (-1;9), 4 (101;9) 4. Nhấn Save 5. Quan sát thông báo lỗi và danh sách | G7: Lưu thành công, hiển thị thông báo "New data added" màu xanh, form đóng; bản ghi mới xuất hiện trong danh sách với dữ liệu đúng như đã nhập | H7: Không lưu được; báo lỗi định dạng; Không phát sinh bản ghi mới trong danh sách | I7: Major | J7: Medium | K7: Open | O7: TC-FB-033, TC-FB-034, TC-FB-035
A8: BUG-005 | B8: Cho phép lưu Project Name và Note với dữ liệu toàn khoảng trắng | C8: Add new Buying | F8: 1. Vào Pricing > FCL Pricing > FCL Buying 2. Nhấn nút Add New Buying để mở form tạo mới 3. Chọn Supplier, Place From, Place To, Mode Of Transport, Weight Range, Container Type; nhập Price (Service Type, Currency, VAT Rate giữ mặc định); nhập chỉ khoảng trắng vào Project Name và Note 4. Nhấn Save 5. Mở lại bản ghi | G8: Lưu thành công, hiển thị thông báo "New data added" màu xanh, form đóng; bản ghi mới xuất hiện trong danh sách với dữ liệu đúng như đã nhập | H8: Hệ thống tự cắt khoảng trắng (trường để trống) hoặc báo lỗi rõ ràng; không lưu chuỗi toàn khoảng trắng | I8: Minor | J8: Low | K8: Open | O8: TC-FB-037
A9: BUG-006 | B9: Thông báo "New data added" hiển thị màu đỏ và không tạo bản ghi khi Project Name quá dài | C9: Add new Buying | F9: 1. Vào Pricing > FCL Pricing > FCL Buying 2. Nhấn nút Add New Buying để mở form tạo mới 3. Chọn Supplier, Place From, Place To, Mode Of Transport, Weight Range, Container Type; nhập Price (Service Type, Currency, VAT Rate giữ mặc định); nhập Project Name 300 ký tự 4. Nhấn Save 5. Quan sát kết quả | G9: Hiển thị thông báo New data added nhưng màu đỏ, form tạo mới giữ nguyên, danh sách không hiện thị dữ liệu mới | H9: Nếu vượt giới hạn: báo lỗi màu đỏ nêu rõ trường và độ dài tối đa, không hiện 'New data added'. Nếu hợp lệ: thông báo màu thành công, form đóng, bản ghi xuất hiện trong danh sách | I9: Minor | J9: Low | K9: Open | O9: TC-FB-039
A10: BUG-007 | B10: Cho phép thực hiện 2 hành động trái ngược nhau trên cùng 1 bản ghi khi mở 2 tab | C10: Accept và Reject | F10: 1. Vào Pricing > FCL Pricing > FCL Buying 2. Mở cùng 1 bản ghi ở cả Tab 1 và Tab 2 3. Tại Tab 1 chọn Accept và xác nhận 4. Tại Tab 2 chọn Reject (kèm ghi chú) và xác nhận | G10: Tab 1: Hiển thị thông báo thành công; bản ghi rời tab Pending, xuất hiện ở tab Accepted; số đếm 2 tab thay đổi đúng. Tab 2: Hiển thị thông báo thành công; bản ghi rời tab Pending, xuất hiện ở tab Rejected; số đếm 2 tab thay đổi đúng | H10: Tab 1: Hiển thị thông báo thành công; bản ghi rời tab Pending, xuất hiện ở tab Accepted; số đếm 2 tab thay đổi đúng. Tab 2: Hệ thống chặn lại, hiển thị thông báo lỗi, không cho phép từ chối đè lên và tự động làm mới lại dữ liệu hiển thị. | I10: Critical | J10: High | K10: Open | O10: TC-FB-087
